Workbook

Sheet Raw
A1: OrderID | B1: OrderDate | C1: ShipDate | D1: Region | E1: Country | F1: State | G1: City | H1: Category | I1: SubCategory | J1: ProductName | K1: Sales | L1: Quantity | M1: Discount | N1: Profit | O1: CustomerID | P1: CustomerName | Q1: Segment | R1: ShippingMode
A2: CA-10001 | B2: 44929 | C2: 44934 | D2: APAC | E2: India | F2: Maharashtra | G2: Nagpur | H2: Technology | I2: Laptops | J2: Lenovo ThinkPad L14 | K2: 82000 | L2: 1 | M2: 0.1 | N2: 6500 | O2: C-001 | P2: Ravi Sharma | Q2: Corporate | R2: Standard Class
A3: CA-10002 | B3: 44931 | C3: 44937 | D3: APAC | E3: India | F3: Karnataka | G3: Bengaluru | H3: Furniture | I3: Chairs | J3: ErgoChair Pro | K3: 12500 | L3: 2 | M3: 0.2 | N3: -1500 | O3: C-002 | P3: Anita Rao | Q3: Consumer | R3: Standard Class
A4: CA-10003 | B4: 44936 | C4: 44941 | D4: Europe | E4: Germany | F4: Bavaria | G4: Munich | H4: Office Supplies | I4: Paper | J4: Premium A4 Copier Paper | K4: 350 | L4: 5 | M4: 0 | N4: 120 | O4: C-003 | P4: Julia Becker | Q4: Home Office | R4: Second Class
A5: CA-10004 | B5: 44938 | C5: 44943 | D5: US | E5: USA | F5: New York | G5: New York | H5: Technology | I5: Phones | J5: iPhone 14 Pro | K5: 120000 | L5: 1 | M5: 0.05 | N5: 9000 | O5: C-004 | P5: Michael Lee | Q5: Corporate | R5: First Class
A6: CA-10005 | B6: 44939 | C6: 44944 | D6: US | E6: USA | F6: California | G6: Los Angeles | H6: Furniture | I6: Tables | J6: Wooden Work Table | K6: 18000 | L6: 1 | M6: 0.25 | N6: -2200 | O6: C-005 | P6: Sarah Jones | Q6: Consumer | R6: Standard Class
A7: CA-10006 | B7: 44946 | C7: 44951 | D7: APAC | E7: India | F7: Delhi | G7: Delhi | H7: Technology | I7: Accessories | J7: Logitech MX Mouse | K7: 4500 | L7: 1 | M7: 0 | N7: 900 | O7: C-006 | P7: Aditya Verma | Q7: Consumer | R7: Second Class
A8: CA-10007 | B8: 44948 | C8: 44952 | D8: APAC | E8: India | F8: Tamil Nadu | G8: Chennai | H8: Office Supplies | I8: Binders | J8: Executive Ring Binder | K8: 900 | L8: 3 | M8: 0.1 | N8: 100 | O8: C-007 | P8: Pooja Iyer | Q8: Home Office | R8: Standard Class
A9: CA-10008 | B9: 44951 | C9: 44956 | D9: Europe | E9: France | F9: Île-de-France | G9: Paris | H9: Furniture | I9: Furnishings | J9: Decorative Lamp | K9: 3200 | L9: 2 | M9: 0.15 | N9: -400 | O9: C-008 | P9: Louis Martin | Q9: Consumer | R9: Second Class
A10: CA-10009 | B10: 44953 | C10: 44958 | D10: US | E10: USA | F10: Texas | G10: Houston | H10: Technology | I10: Laptops | J10: HP EliteBook 840 | K10: 72000 | L10: 1 | M10: 0.2 | N10: -3000 | O10: C-009 | P10: John Miller | Q10: Corporate | R10: Standard Class
A11: CA-10010 | B11: 44959 | C11: 44963 | D11: APAC | E11: India | F11: Gujarat | G11: Ahmedabad | H11: Office Supplies | I11: Paper | J11: A4 Notebook Spiral | K11: 150 | L11: 2 | M11: 0 | N11: 40 | O11: C-010 | P11: Nirali Patel | Q11: Consumer | R11: Second Class
A12: CA-10011 | B12: 44960 | C12: 44965 | D12: APAC | E12: India | F12: Maharashtra | G12: Mumbai | H12: Technology | I12: Phones | J12: Samsung S23 Ultra | K12: 104000 | L12: 1 | M12: 0.1 | N12: 7000 | O12: C-011 | P12: Karan Malhotra | Q12: Home Office | R12: Second Class
A13: CA-10012 | B13: 44962 | C13: 44967 | D13: Europe | E13: UK | F13: England | G13: London | H13: Furniture | I13: Chairs | J13: Leather Office Chair | K13: 15000 | L13: 1 | M13: 0.2 | N13: -2500 | O13: C-012 | P13: Ava Brown | Q13: Consumer | R13: Standard Class
... A51: CA-10050 | B51: 45044 | C51: 45049 | D51: APAC | E51: India | F51: Uttar Pradesh | G51: Noida | H51: Technology | I51: Laptops | J51: Asus Vivobook 15 | K51: 46000 | L51: 1 | M51: 0.2 | N51: -1500 | O51: C-050 | P51: Rishabh Goel | Q51: Corporate | R51: Standard Class

Sheet Clean
A1: OrderID | B1: OrderDate | C1: ShipDate | D1: Region_Final | E1: Country | F1: State | G1: City | H1: Category | I1: SubCategory | J1: ProductName | K1: Sales | L1: Quantity | M1: Discount (%) | N1: Profit | O1: CustomerID | P1: CustomerName | Q1: Segment | R1: ShippingMode | S1: Sales($) | T1: Current-Rate | U1: Category_Clean | V1: Subcategory_Clean | W1: Profit_Margin | X1: Discount_Amount | Y1: Year | Z1: Month | AA1: Order_Month_Name
A2: CA-10001 | B2: 44929 | C2: 44934 | D2: =IF(F2="","Unknown",IFERROR(VLOOKUP(F2,lookup!$A:$B,2,FALSE),"Unknown")) -> APAC | E2: India | F2: Maharashtra | G2: Nagpur | H2: Technology | I2: Laptops | J2: Lenovo ThinkPad L14 | K2: 82000 | L2: 1 | M2: 0.1 | N2: 6500 | O2: C-001 | P2: Ravi Sharma | Q2: Corporate | R2: Standard Class | S2: =K2/$T$2 -> 911.8203 | T2: 89.93 | U2: =TRIM(PROPER(H2)) -> Technology | V2: =TRIM(PROPER(I2)) -> Laptops | W2: =IF(K2=0,0,K2/N2) -> 12.615385 | X2: =K2*M2 -> 8200 | Y2: =YEAR(B2) -> 2023 | Z2: =TEXT(B2,"YYYY-MM") -> 2023-01 | AA2: =TEXT(B2,"MMM,YYYY") -> Jan,2023
A3: CA-10002 | B3: 44931 | C3: 44935 | D3: =IF(F3="","Unknown",IFERROR(VLOOKUP(F3,lookup!$A:$B,2,FALSE),"Unknown")) -> APAC | E3: India | F3: Karnataka | G3: Bengaluru | H3: Furniture | I3: Chairs | J3: ErgoChair Pro | K3: 12500 | L3: 2 | M3: 0.2 | N3: -1500 | O3: C-002 | P3: Anita Rao | Q3: Consumer | R3: Standard Class | S3: =K3/$T$2 -> 138.997 | T3: 89.93 | U3: =TRIM(PROPER(H3)) -> Furniture | V3: =TRIM(PROPER(I3)) -> Chairs | W3: =IF(K3=0,0,K3/N3) -> -8.3333333 | X3: =K3*M3 -> 2500 | Y3: =YEAR(B3) -> 2023 | Z3: =TEXT(B3,"YYYY-MM") -> 2023-01 | AA3: =TEXT(B3,"MMM,YYYY") -> Jan,2023
A4: CA-10003 | B4: 44936 | C4: 44936 | D4: =IF(F4="","Unknown",IFERROR(VLOOKUP(F4,lookup!$A:$B,2,FALSE),"Unknown")) -> Europe | E4: Germany | F4: Bavaria | G4: Munich | H4: Office Supplies | I4: Paper | J4: Premium A4 Copier Paper | K4: 350 | L4: 5 | M4: 0 | N4: 120 | O4: C-003 | P4: Julia Becker | Q4: Home Office | R4: Second Class | S4: =K4/$T$2 -> 3.8919159 | T4: 89.93 | U4: =TRIM(PROPER(H4)) -> Office Supplies | V4: =TRIM(PROPER(I4)) -> Paper | W4: =IF(K4=0,0,K4/N4) -> 2.9166667 | X4: =K4*M4 -> 0 | Y4: =YEAR(B4) -> 2023 | Z4: =TEXT(B4,"YYYY-MM") -> 2023-01 | AA4: =TEXT(B4,"MMM,YYYY") -> Jan,2023
A5: CA-10004 | B5: 44938 | C5: 44937 | D5: =IF(F5="","Unknown",IFERROR(VLOOKUP(F5,lookup!$A:$B,2,FALSE),"Unknown")) -> US | E5: USA | F5: New York | G5: New York | H5: Technology | I5: Phones | J5: iPhone 14 Pro | K5: 120000 | L5: 1 | M5: 0.05 | N5: 9000 | O5: C-004 | P5: Michael Lee | Q5: Corporate | R5: First Class | S5: =K5/$T$2 -> 1334.3712 | T5: 89.93 | U5: =TRIM(PROPER(H5)) -> Technology | V5: =TRIM(PROPER(I5)) -> Phones | W5: =IF(K5=0,0,K5/N5) -> 13.333333 | X5: =K5*M5 -> 6000 | Y5: =YEAR(B5) -> 2023 | Z5: =TEXT(B5,"YYYY-MM") -> 2023-01 | AA5: =TEXT(B5,"MMM,YYYY") -> Jan,2023
A6: CA-10005 | B6: 44939 | C6: 44938 | D6: =IF(F6="","Unknown",IFERROR(VLOOKUP(F6,lookup!$A:$B,2,FALSE),"Unknown")) -> US | E6: USA | F6: California | G6: Los Angeles | H6: Furniture | I6: Tables | J6: Wooden Work Table | K6: 18000 | L6: 1 | M6: 0.25 | N6: -2200 | O6: C-005 | P6: Sarah Jones | Q6: Consumer | R6: Standard Class | S6: =K6/$T$2 -> 200.15568 | T6: 89.93 | U6: =TRIM(PROPER(H6)) -> Furniture | V6: =TRIM(PROPER(I6)) -> Tables | W6: =IF(K6=0,0,K6/N6) -> -8.1818182 | X6: =K6*M6 -> 4500 | Y6: =YEAR(B6) -> 2023 | Z6: =TEXT(B6,"YYYY-MM") -> 2023-01 | AA6: =TEXT(B6,"MMM,YYYY") -> Jan,2023
A7: CA-10006 | B7: 44946 | C7: 44939 | D7: =IF(F7="","Unknown",IFERROR(VLOOKUP(F7,lookup!$A:$B,2,FALSE),"Unknown")) -> APAC | E7: India | F7: Delhi | G7: Delhi | H7: Technology | I7: Accessories | J7: Logitech MX Mouse | K7: 4500 | L7: 1 | M7: 0 | N7: 900 | O7: C-006 | P7: Aditya Verma | Q7: Consumer | R7: Second Class | S7: =K7/$T$2 -> 50.038919 | T7: 89.93 | U7: =TRIM(PROPER(H7)) -> Technology | V7: =TRIM(PROPER(I7)) -> Accessories | W7: =IF(K7=0,0,K7/N7) -> 5 | X7: =K7*M7 -> 0 | Y7: =YEAR(B7) -> 2023 | Z7: =TEXT(B7,"YYYY-MM") -> 2023-01 | AA7: =TEXT(B7,"MMM,YYYY") -> Jan,2023
A8: CA-10007 | B8: 44948 | C8: 44940 | D8: =IF(F8="","Unknown",IFERROR(VLOOKUP(F8,lookup!$A:$B,2,FALSE),"Unknown")) -> APAC | E8: India | F8: Tamil Nadu | G8: Chennai | H8: Office Supplies | I8: Binders | J8: Executive Ring Binder | K8: 900 | L8: 3 | M8: 0.1 | N8: 100 | O8: C-007 | P8: Pooja Iyer | Q8: Home Office | R8: Standard Class | S8: =K8/$T$2 -> 10.007784 | T8: 89.93 | U8: =TRIM(PROPER(H8)) -> Office Supplies | V8: =TRIM(PROPER(I8)) -> Binders | W8: =IF(K8=0,0,K8/N8) -> 9 | X8: =K8*M8 -> 90 | Y8: =YEAR(B8) -> 2023 | Z8: =TEXT(B8,"YYYY-MM") -> 2023-01 | AA8: =TEXT(B8,"MMM,YYYY") -> Jan,2023
A9: CA-10008 | B9: 44951 | C9: 44941 | D9: =IF(F9="","Unknown",IFERROR(VLOOKUP(F9,lookup!$A:$B,2,FALSE),"Unknown")) -> Europe | E9: France | F9: Île-de-France | G9: Paris | H9: Furniture | I9: Furnishings | J9: Decorative Lamp | K9: 3200 | L9: 2 | M9: 0.15 | N9: -400 | O9: C-008 | P9: Louis Martin | Q9: Consumer | R9: Second Class | S9: =K9/$T$2 -> 35.583231 | T9: 89.93 | U9: =TRIM(PROPER(H9)) -> Furniture | V9: =TRIM(PROPER(I9)) -> Furnishings | W9: =IF(K9=0,0,K9/N9) -> -8 | X9: =K9*M9 -> 480 | Y9: =YEAR(B9) -> 2023 | Z9: =TEXT(B9,"YYYY-MM") -> 2023-01 | AA9: =TEXT(B9,"MMM,YYYY") -> Jan,2023
A10: CA-10009 | B10: 44953 | C10: 44942 | D10: =IF(F10="","Unknown",IFERROR(VLOOKUP(F10,lookup!$A:$B,2,FALSE),"Unknown")) -> US | E10: USA | F10: Texas | G10: Houston | H10: Technology | I10: Laptops | J10: HP EliteBook 840 | K10: 72000 | L10: 1 | M10: 0.2 | N10: -3000 | O10: C-009 | P10: John Miller | Q10: Corporate | R10: Standard Class | S10: =K10/$T$2 -> 800.62271 | T10: 89.93 | U10: =TRIM(PROPER(H10)) -> Technology | V10: =TRIM(PROPER(I10)) -> Laptops | W10: =IF(K10=0,0,K10/N10) -> -24 | X10: =K10*M10 -> 14400 | Y10: =YEAR(B10) -> 2023 | Z10: =TEXT(B10,"YYYY-MM") -> 2023-01 | AA10: =TEXT(B10,"MMM,YYYY") -> Jan,2023
A11: CA-10010 | B11: 44959 | C11: 44943 | D11: =IF(F11="","Unknown",IFERROR(VLOOKUP(F11,lookup!$A:$B,2,FALSE),"Unknown")) -> APAC | E11: India | F11: Gujarat | G11: Ahmedabad | H11: Office Supplies | I11: Paper | J11: A4 Notebook Spiral | K11: 150 | L11: 2 | M11: 0 | N11: 40 | O11: C-010 | P11: Nirali Patel | Q11: Consumer | R11: Second Class | S11: =K11/$T$2 -> 1.667964 | T11: 89.93 | U11: =TRIM(PROPER(H11)) -> Office Supplies | V11: =TRIM(PROPER(I11)) -> Paper | W11: =IF(K11=0,0,K11/N11) -> 3.75 | X11: =K11*M11 -> 0 | Y11: =YEAR(B11) -> 2023 | Z11: =TEXT(B11,"YYYY-MM") -> 2023-02 | AA11: =TEXT(B11,"MMM,YYYY") -> Feb,2023
A12: CA-10011 | B12: 44960 | C12: 44944 | D12: =IF(F12="","Unknown",IFERROR(VLOOKUP(F12,lookup!$A:$B,2,FALSE),"Unknown")) -> APAC | E12: India | F12: Maharashtra | G12: Mumbai | H12: Technology | I12: Phones | J12: Samsung S23 Ultra | K12: 104000 | L12: 1 | M12: 0.1 | N12: 7000 | O12: C-011 | P12: Karan Malhotra | Q12: Home Office | R12: Second Class | S12: =K12/$T$2 -> 1156.455 | T12: 89.93 | U12: =TRIM(PROPER(H12)) -> Technology | V12: =TRIM(PROPER(I12)) -> Phones | W12: =IF(K12=0,0,K12/N12) -> 14.857143 | X12: =K12*M12 -> 10400 | Y12: =YEAR(B12) -> 2023 | Z12: =TEXT(B12,"YYYY-MM") -> 2023-02 | AA12: =TEXT(B12,"MMM,YYYY") -> Feb,2023
A13: CA-10012 | B13: 44962 | C13: 44945 | D13: =IF(F13="","Unknown",IFERROR(VLOOKUP(F13,lookup!$A:$B,2,FALSE),"Unknown")) -> Europe | E13: UK | F13: England | G13: London | H13: Furniture | I13: Chairs | J13: Leather Office Chair | K13: 15000 | L13: 1 | M13: 0.2 | N13: -2500 | O13: C-012 | P13: Ava Brown | Q13: Consumer | R13: Standard Class | S13: =K13/$T$2 -> 166.7964 | T13: 89.93 | U13: =TRIM(PROPER(H13)) -> Furniture | V13: =TRIM(PROPER(I13)) -> Chairs | W13: =IF(K13=0,0,K13/N13) -> -6 | X13: =K13*M13 -> 3000 | Y13: =YEAR(B13) -> 2023 | Z13: =TEXT(B13,"YYYY-MM") -> 2023-02 | AA13: =TEXT(B13,"MMM,YYYY") -> Feb,2023
... A51: CA-10050 | B51: 45044 | C51: 44983 | D51: =IF(F51="","Unknown",IFERROR(VLOOKUP(F51,lookup!$A:$B,2,FALSE),"Unknown")) -> APAC | E51: India | F51: Uttar Pradesh | G51: Noida | H51: Technology | I51: Laptops | J51: Asus Vivobook 15 | K51: 46000 | L51: 1 | M51: 0.2 | N51: -1500 | O51: C-050 | P51: Rishabh Goel | Q51: Corporate | R51: Standard Class | S51: =K51/$T$2 -> 511.50895 | T51: 89.93 | U51: =TRIM(PROPER(H51)) -> Technology | V51: =TRIM(PROPER(I51)) -> Laptops | W51: =IF(K51=0,0,K51/N51) -> -30.666667 | X51: =K51*M51 -> 9200 | Y51: =YEAR(B51) -> 2023 | Z51: =TEXT(B51,"YYYY-MM") -> 2023-04 | AA51: =TEXT(B51,"MMM,YYYY") -> Apr,2023
A52: CA-10051 | U52: =TRIM(PROPER(H52)) | V52: =TRIM(PROPER(I52))
A53: CA-10052 | U53: =TRIM(PROPER(H53)) | V53: =TRIM(PROPER(I53))
A54: CA-10053 | U54: =TRIM(PROPER(H54)) | V54: =TRIM(PROPER(I54))
A55: CA-10054 | U55: =TRIM(PROPER(H55)) | V55: =TRIM(PROPER(I55))
A56: CA-10055 | U56: =TRIM(PROPER(H56)) | V56: =TRIM(PROPER(I56))
A57: CA-10056 | U57: =TRIM(PROPER(H57)) | V57: =TRIM(PROPER(I57))
A58: CA-10057 | U58: =TRIM(PROPER(H58)) | V58: =TRIM(PROPER(I58))
A59: CA-10058 | U59: =TRIM(PROPER(H59)) | V59: =TRIM(PROPER(I59))
U60: =TRIM(PROPER(H60)) | V60: =TRIM(PROPER(I60))
U61: =TRIM(PROPER(H61)) | V61: =TRIM(PROPER(I61))
U62: =TRIM(PROPER(H62)) | V62: =TRIM(PROPER(I62))
U63: =TRIM(PROPER(H63)) | V63: =TRIM(PROPER(I63))
U64: =TRIM(PROPER(H64)) | V64: =TRIM(PROPER(I64))
U65: =TRIM(PROPER(H65)) | V65: =TRIM(PROPER(I65))
U66: =TRIM(PROPER(H66)) | V66: =TRIM(PROPER(I66))
U67: =TRIM(PROPER(H67)) | V67: =TRIM(PROPER(I67))
U68: =TRIM(PROPER(H68)) | V68: =TRIM(PROPER(I68))
U69: =TRIM(PROPER(H69)) | V69: =TRIM(PROPER(I69))
U70: =TRIM(PROPER(H70)) | V70: =TRIM(PROPER(I70))
U71: =TRIM(PROPER(H71)) | V71: =TRIM(PROPER(I71))
... U120: =TRIM(PROPER(H120)) | V120: =TRIM(PROPER(I120))

Sheet lookup
A1: State | B1: Region
A2: Maharashtra | B2: APAC
A3: Karnataka | B3: APAC
A4: Bavaria | B4: Europe
A5: New York | B5: US
A6: California | B6: US
A7: Delhi | B7: APAC
A8: Tamil Nadu | B8: APAC
A9: Île-de-France | B9: Europe
A10: Texas | B10: US
A11: Gujarat | B11: APAC
A12: Maharashtra | B12: APAC
... A51: Uttar Pradesh | B51: APAC

Sheet Pivot
A1: OrderDate | B1: Region_Final | C1: Category | D1: SubCategory | E1: Sales | F1: Profit
A2: 44929 | B2: APAC | C2: Technology | D2: Laptops | E2: 82000 | F2: 6500 | G2: Row Labels | H2: Sum of Sales | I2: Sum of Profit
A3: 44931 | B3: APAC | C3: Furniture | D3: Chairs | E3: 12500 | F3: -1500 | G3: APAC | H3: 376370 | I3: 2100
A4: 44936 | B4: Europe | C4: Office Supplies | D4: Paper | E4: 350 | F4: 120 | G4: Europe | H4: 283520 | I4: -1060
A5: 44938 | B5: US | C5: Technology | D5: Phones | E5: 120000 | F5: 9000 | G5: US | H5: 572900 | I5: 24900
A6: 44939 | B6: US | C6: Furniture | D6: Tables | E6: 18000 | F6: -2200 | G6: Grand Total | H6: 1232790 | I6: 25940
A7: 44946 | B7: APAC | C7: Technology | D7: Accessories | E7: 4500 | F7: 900
A8: 44948 | B8: APAC | C8: Office Supplies | D8: Binders | E8: 900 | F8: 100
A9: 44951 | B9: Europe | C9: Furniture | D9: Furnishings | E9: 3200 | F9: -400
A10: 44953 | B10: US | C10: Technology | D10: Laptops | E10: 72000 | F10: -3000 | G10: Row Labels | H10: Sum of Sales | I10: Sum of Profit
A11: 44959 | B11: APAC | C11: Office Supplies | D11: Paper | E11: 150 | F11: 40 | G11: Furniture | H11: 172200 | I11: -13800
A12: 44960 | B12: APAC | C12: Technology | D12: Phones | E12: 104000 | F12: 7000 | G12: Chairs | H12: 53700 | I12: -7050
A13: 44962 | B13: Europe | C13: Furniture | D13: Chairs | E13: 15000 | F13: -2500 | G13: Furnishings | H13: 13500 | I13: -750
A14: 44966 | B14: US | C14: Technology | D14: Accessories | E14: 6200 | F14: 500 | G14: Tables | H14: 105000 | I14: -6000
A15: 44968 | B15: APAC | C15: Furniture | D15: Tables | E15: 22000 | F15: -4000 | G15: Office Supplies | H15: 6490 | I15: 990
A16: 44972 | B16: Europe | C16: Office Supplies | D16: Paper | E16: 420 | F16: 160 | G16: Binders | H16: 4430 | I16: 270
A17: 44975 | B17: US | C17: Technology | D17: Phones | E17: 78000 | F17: 5000 | G17: Paper | H17: 2060 | I17: 720
A18: 44977 | B18: APAC | C18: Technology | D18: Accessories | E18: 2500 | F18: 200 | G18: Technology | H18: 1054100 | I18: 38750
A19: 44979 | B19: APAC | C19: Furniture | D19: Furnishings | E19: 1800 | F19: 100 | G19: Accessories | H19: 51100 | I19: 4150
A20: 44981 | B20: Europe | C20: Technology | D20: Phones | E20: 58000 | F20: -5000 | G20: Laptops | H20: 483000 | I20: 17500
A21: 44983 | B21: APAC | C21: Office Supplies | D21: Binders | E21: 850 | F21: 150 | G21: Phones | H21: 520000 | I21: 17100
A22: 44988 | B22: US | C22: Technology | D22: Laptops | E22: 105000 | F22: 8000 | G22: (blank)
A23: 44989 | B23: APAC | C23: Furniture | D23: Chairs | E23: 1100 | F23: -200 | G23: (blank)
A24: 44990 | B24: Europe | C24: Technology | D24: Accessories | E24: 5400 | F24: 300 | G24: Grand Total | H24: 1232790 | I24: 25940
A25: 44992 | B25: APAC | C25: Office Supplies | D25: Paper | E25: 280 | F25: 120
A26: 44993 | B26: US | C26: Furniture | D26: Tables | E26: 32000 | F26: 1800
A27: 44996 | B27: APAC | C27: Technology | D27: Phones | E27: 24000 | F27: -3000
A28: 44999 | B28: Europe | C28: Furniture | D28: Chairs | E28: 17000 | F28: -2000 | G28: Row Labels | H28: Sum of Sales
A29: 45001 | B29: APAC | C29: Office Supplies | D29: Binders | E29: 780 | F29: 50 | G29: (blank)
A30: 45003 | B30: US | C30: Technology | D30: Accessories | E30: 21000 | F30: 1500 | G30: Jan | H30: 313450
A31: 45005 | B31: Europe | C31: Technology | D31: Phones | E31: 41000 | F31: -2000 | G31: Feb | H31: 288920
A32: 45007 | B32: APAC | C32: Office Supplies | D32: Paper | E32: 300 | F32: 140 | G32: Mar | H32: 259760
A33: 45010 | B33: APAC | C33: Furniture | D33: Furnishings | E33: 2200 | F33: -150 | G33: Apr | H33: 370660
A34: 45012 | B34: US | C34: Technology | D34: Accessories | E34: 3200 | F34: 200 | G34: Grand Total | H34: 1232790
A35: 45013 | B35: APAC | C35: Furniture | D35: Chairs | E35: 5200 | F35: -600
A36: 45015 | B36: Europe | C36: Office Supplies | D36: Binders | E36: 1300 | F36: -50
A37: 45017 | B37: APAC | C37: Technology | D37: Laptops | E37: 58000 | F37: -2000
A38: 45018 | B38: Europe | C38: Furniture | D38: Tables | E38: 14000 | F38: 700
A39: 45020 | B39: US | C39: Technology | D39: Phones | E39: 65000 | F39: 4500
A40: 45022 | B40: APAC | C40: Office Supplies | D40: Paper | E40: 310 | F40: 80
...

Sheet Assumptions
A1: Assumptions
A3: 1. Data Source Assumptions
A5: The dataset represents historical retail transaction data and is assumed to be complete and accurate as provided.
A7: No external enrichment (third-party datasets) was applied beyond internally derived lookup tables.
A9: Currency values are assumed to be consistent across all records unless otherwise stated.
A11: 2. Missing Data Handling
A13: Records with missing Order ID or Sales values were removed, as these fields are critical for transactional analysis.
A15: Missing or invalid values in non-critical categorical fields (e.g., Region) were replaced using lookup-based derivation.
A17: Any categorical value that could not be confidently derived was labeled as “Unknown” to prevent incorrect aggregation.
A19: 3. Geographic Mapping Assumptions
A21: Regional classification was derived using a predefined State → Region lookup table.
A23: Region values present in the raw dataset were not trusted and were recalculated to ensure consistency.
... A75: Customer behavior analysis is limited to historical transaction data available in the dataset.

Sheet Insights
A1: Row Labels | B1: Sum of Profit | C1: Sum of Sales | I1: Discount (%) | J1: Profit_Margin
A2: Laptops | B2: 17500 | C2: 483000 | I2: 0.1 | J2: 12.615385
A3: Phones | B3: 17100 | C3: 520000 | I3: 0.2 | J3: -8.3333333
A4: Accessories | B4: 4150 | C4: 51100 | I4: 0 | J4: 2.9166667
A5: Paper | B5: 720 | C5: 2060 | I5: 0.05 | J5: 13.333333
A6: Binders | B6: 270 | C6: 4430 | I6: 0.25 | J6: -8.1818182
A7: (blank) | I7: 0 | J7: 5
A8: Furnishings | B8: -750 | C8: 13500 | I8: 0.1 | J8: 9
A9: Tables | B9: -6000 | C9: 105000 | I9: 0.15 | J9: -8
A10: Chairs | B10: -7050 | C10: 53700 | I10: 0.2 | J10: -24
A11: Grand Total | B11: 25940 | C11: 1232790 | I11: 0 | J11: 3.75
I12: 0.1 | J12: 14.857143
I13: 0.2 | J13: -6
I14: 0.15 | J14: 12.4
I15: 0.3 | J15: -5.5
I16: 0 | J16: 2.625
I17: 0.05 | J17: 15.6
I18: 0.2 | J18: 12.5
I19: 0.1 | J19: 18
I20: 0.25 | J20: -11.6
I21: 0 | J21: 5.6666667
I22: 0.1 | J22: 13.125
I23: 0.2 | J23: -5.5
... I51: 0.2 | J51: -30.666667

Sheet RFM
A1: CustomerID | B1: Recency (days) | C1: Frequency | D1: Monetary (₹) | E1: R | F1: F | G1: M | H1: Segment | I1: Max Date | J1: OrderDate
A2: C-001 | B2: 116 | C2: 1 | D2: 82000 | E2: 1 | F2: 1 | G2: 5 | H2: Big Spender (At Risk) | I2: 45044 | J2: 44929
A3: C-002 | B3: 114 | C3: 1 | D3: 12500 | E3: 1 | F3: 1 | G3: 3 | H3: Lost Customers | I3: 45044 | J3: 44931
A4: C-003 | B4: 109 | C4: 1 | D4: 350 | E4: 1 | F4: 1 | G4: 1 | H4: Lost Customers | I4: 45044 | J4: 44936
A5: C-004 | B5: 107 | C5: 1 | D5: 120000 | E5: 1 | F5: 1 | G5: 5 | H5: Big Spender (At Risk) | I5: 45044 | J5: 44938
A6: C-005 | B6: 106 | C6: 1 | D6: 18000 | E6: 1 | F6: 1 | G6: 4 | H6: Big Spender (At Risk) | I6: 45044 | J6: 44939
A7: C-006 | B7: 99 | C7: 1 | D7: 4500 | E7: 1 | F7: 1 | G7: 3 | H7: Lost Customers | I7: 45044 | J7: 44946
A8: C-007 | B8: 97 | C8: 1 | D8: 900 | E8: 1 | F8: 1 | G8: 2 | H8: Lost Customers | I8: 45044 | J8: 44948
A9: C-008 | B9: 94 | C9: 1 | D9: 3200 | E9: 1 | F9: 1 | G9: 2 | H9: Lost Customers | I9: 45044 | J9: 44951
A10: C-009 | B10: 92 | C10: 1 | D10: 72000 | E10: 1 | F10: 1 | G10: 5 | H10: Big Spender (At Risk) | I10: 45044 | J10: 44953
A11: C-010 | B11: 86 | C11: 1 | D11: 150 | E11: 1 | F11: 1 | G11: 1 | H11: Lost Customers | I11: 45044 | J11: 44959
A12: C-011 | B12: 85 | C12: 1 | D12: 104000 | E12: 2 | F12: 2 | G12: 5 | H12: Big Spender (At Risk) | I12: 45044 | J12: 44960
A13: C-012 | B13: 83 | C13: 1 | D13: 15000 | E13: 2 | F13: 2 | G13: 3 | H13: Average Customers | I13: 45044 | J13: 44962
... A51: C-050 | B51: 1 | C51: 1 | D51: 46000 | E51: 5 | F51: 5 | G51: 4 | H51: Champions | I51: 45044 | J51: 45044
